[2020-04-01 15:47:06,751][fake_learner.py][line:  65][    INFO] something wrong with coordinator, HTTPConnectionPool(host='10.5.36.31', port=18294): Max retries exceeded with url: /coordinator/register_learner (Caused by NewConnectionError('<urllib3.connection.HTTPConnection object at 0x7faf65c24f98>: Failed to establish a new connection: [Errno 111] Connection refused',))
[2020-04-01 15:47:16,765][fake_learner.py][line:  65][    INFO] something wrong with coordinator, HTTPConnectionPool(host='10.5.36.31', port=18294): Max retries exceeded with url: /coordinator/register_learner (Caused by NewConnectionError('<urllib3.connection.HTTPConnection object at 0x7faf634616d8>: Failed to establish a new connection: [Errno 111] Connection refused',))
[2020-04-01 15:47:26,814][fake_learner.py][line:  65][    INFO] something wrong with coordinator, HTTPConnectionPool(host='10.5.36.31', port=18294): Max retries exceeded with url: /coordinator/register_learner (Caused by NewConnectionError('<urllib3.connection.HTTPConnection object at 0x7faf63461278>: Failed to establish a new connection: [Errno 111] Connection refused',))
[2020-04-01 15:47:36,836][fake_learner.py][line:  46][    INFO] [UP] check train thread 
[2020-04-01 15:58:01,518][fake_learner.py][line:  65][    INFO] something wrong with coordinator, HTTPConnectionPool(host='10.5.36.31', port=18294): Max retries exceeded with url: /coordinator/register_learner (Caused by NewConnectionError('<urllib3.connection.HTTPConnection object at 0x7fe45b440f60>: Failed to establish a new connection: [Errno 111] Connection refused',))
[2020-04-01 15:58:11,535][fake_learner.py][line:  65][    INFO] something wrong with coordinator, HTTPConnectionPool(host='10.5.36.31', port=18294): Max retries exceeded with url: /coordinator/register_learner (Caused by NewConnectionError('<urllib3.connection.HTTPConnection object at 0x7fe45b3d16a0>: Failed to establish a new connection: [Errno 111] Connection refused',))
[2020-04-01 15:58:21,586][fake_learner.py][line:  65][    INFO] something wrong with coordinator, HTTPConnectionPool(host='10.5.36.31', port=18294): Max retries exceeded with url: /coordinator/register_learner (Caused by NewConnectionError('<urllib3.connection.HTTPConnection object at 0x7fe45b440630>: Failed to establish a new connection: [Errno 111] Connection refused',))
[2020-04-01 15:58:31,606][fake_learner.py][line:  65][    INFO] something wrong with coordinator, HTTPConnectionPool(host='10.5.36.31', port=18294): Max retries exceeded with url: /coordinator/register_learner (Caused by NewConnectionError('<urllib3.connection.HTTPConnection object at 0x7fe45b3d1320>: Failed to establish a new connection: [Errno 111] Connection refused',))
[2020-04-01 15:58:41,623][fake_learner.py][line:  65][    INFO] something wrong with coordinator, HTTPConnectionPool(host='10.5.36.31', port=18294): Max retries exceeded with url: /coordinator/register_learner (Caused by NewConnectionError('<urllib3.connection.HTTPConnection object at 0x7fe45b3d1d68>: Failed to establish a new connection: [Errno 111] Connection refused',))
[2020-04-01 15:58:51,641][fake_learner.py][line:  65][    INFO] something wrong with coordinator, HTTPConnectionPool(host='10.5.36.31', port=18294): Max retries exceeded with url: /coordinator/register_learner (Caused by NewConnectionError('<urllib3.connection.HTTPConnection object at 0x7fe45b3d7240>: Failed to establish a new connection: [Errno 111] Connection refused',))
[2020-04-01 15:59:01,673][fake_learner.py][line:  46][    INFO] [UP] check train thread 
[2020-04-01 16:00:11,444][fake_learner.py][line:  65][    INFO] something wrong with coordinator, HTTPConnectionPool(host='10.5.36.31', port=18294): Max retries exceeded with url: /coordinator/register_learner (Caused by NewConnectionError('<urllib3.connection.HTTPConnection object at 0x7f60e06f6f60>: Failed to establish a new connection: [Errno 111] Connection refused',))
[2020-04-01 16:00:21,507][fake_learner.py][line:  46][    INFO] [UP] check train thread 
[2020-04-01 16:00:55,876][fake_learner.py][line:  65][    INFO] something wrong with coordinator, HTTPConnectionPool(host='10.5.36.31', port=18294): Max retries exceeded with url: /coordinator/register_learner (Caused by NewConnectionError('<urllib3.connection.HTTPConnection object at 0x7f7b37be5f60>: Failed to establish a new connection: [Errno 111] Connection refused',))
[2020-04-01 16:01:05,906][fake_learner.py][line:  46][    INFO] [UP] check train thread 
