[2020-03-31 18:12:39,287][fake_learner.py][line:  65][    INFO] something wrong with coordinator, HTTPConnectionPool(host='10.5.36.31', port=18294): Max retries exceeded with url: /coordinator/register_learner (Caused by NewConnectionError('<urllib3.connection.HTTPConnection object at 0x7f41f7520978>: Failed to establish a new connection: [Errno 111] Connection refused',))
[2020-03-31 18:12:49,301][fake_learner.py][line:  65][    INFO] something wrong with coordinator, HTTPConnectionPool(host='10.5.36.31', port=18294): Max retries exceeded with url: /coordinator/register_learner (Caused by NewConnectionError('<urllib3.connection.HTTPConnection object at 0x7f41f74c50b8>: Failed to establish a new connection: [Errno 111] Connection refused',))
[2020-03-31 18:12:59,355][fake_learner.py][line:  65][    INFO] something wrong with coordinator, HTTPConnectionPool(host='10.5.36.31', port=18294): Max retries exceeded with url: /coordinator/register_learner (Caused by NewConnectionError('<urllib3.connection.HTTPConnection object at 0x7f41f7520cf8>: Failed to establish a new connection: [Errno 111] Connection refused',))
[2020-03-31 18:13:09,373][fake_learner.py][line:  65][    INFO] something wrong with coordinator, HTTPConnectionPool(host='10.5.36.31', port=18294): Max retries exceeded with url: /coordinator/register_learner (Caused by NewConnectionError('<urllib3.connection.HTTPConnection object at 0x7f41f7520128>: Failed to establish a new connection: [Errno 111] Connection refused',))
[2020-03-31 18:13:19,388][fake_learner.py][line:  65][    INFO] something wrong with coordinator, HTTPConnectionPool(host='10.5.36.31', port=18294): Max retries exceeded with url: /coordinator/register_learner (Caused by NewConnectionError('<urllib3.connection.HTTPConnection object at 0x7f41f74c5748>: Failed to establish a new connection: [Errno 111] Connection refused',))
[2020-03-31 18:13:29,404][fake_learner.py][line:  65][    INFO] something wrong with coordinator, HTTPConnectionPool(host='10.5.36.31', port=18294): Max retries exceeded with url: /coordinator/register_learner (Caused by NewConnectionError('<urllib3.connection.HTTPConnection object at 0x7f41f74c5e10>: Failed to establish a new connection: [Errno 111] Connection refused',))
[2020-03-31 18:13:39,414][fake_learner.py][line:  65][    INFO] something wrong with coordinator, HTTPConnectionPool(host='10.5.36.31', port=18294): Max retries exceeded with url: /coordinator/register_learner (Caused by NewConnectionError('<urllib3.connection.HTTPConnection object at 0x7f41f74d6518>: Failed to establish a new connection: [Errno 111] Connection refused',))
[2020-03-31 18:13:49,430][fake_learner.py][line:  65][    INFO] something wrong with coordinator, HTTPConnectionPool(host='10.5.36.31', port=18294): Max retries exceeded with url: /coordinator/register_learner (Caused by NewConnectionError('<urllib3.connection.HTTPConnection object at 0x7f41f74d6be0>: Failed to establish a new connection: [Errno 111] Connection refused',))
[2020-03-31 18:13:59,447][fake_learner.py][line:  65][    INFO] something wrong with coordinator, HTTPConnectionPool(host='10.5.36.31', port=18294): Max retries exceeded with url: /coordinator/register_learner (Caused by NewConnectionError('<urllib3.connection.HTTPConnection object at 0x7f41f74d67f0>: Failed to establish a new connection: [Errno 111] Connection refused',))
[2020-03-31 18:14:09,464][fake_learner.py][line:  65][    INFO] something wrong with coordinator, HTTPConnectionPool(host='10.5.36.31', port=18294): Max retries exceeded with url: /coordinator/register_learner (Caused by NewConnectionError('<urllib3.connection.HTTPConnection object at 0x7f41f74d6128>: Failed to establish a new connection: [Errno 111] Connection refused',))
[2020-03-31 18:14:19,477][fake_learner.py][line:  65][    INFO] something wrong with coordinator, HTTPConnectionPool(host='10.5.36.31', port=18294): Max retries exceeded with url: /coordinator/register_learner (Caused by NewConnectionError('<urllib3.connection.HTTPConnection object at 0x7f41f7520860>: Failed to establish a new connection: [Errno 111] Connection refused',))
[2020-03-31 18:14:29,539][fake_learner.py][line:  65][    INFO] something wrong with coordinator, HTTPConnectionPool(host='10.5.36.31', port=18294): Max retries exceeded with url: /coordinator/register_learner (Caused by NewConnectionError('<urllib3.connection.HTTPConnection object at 0x7f41f7520fd0>: Failed to establish a new connection: [Errno 111] Connection refused',))
[2020-03-31 18:14:39,558][fake_learner.py][line:  65][    INFO] something wrong with coordinator, HTTPConnectionPool(host='10.5.36.31', port=18294): Max retries exceeded with url: /coordinator/register_learner (Caused by NewConnectionError('<urllib3.connection.HTTPConnection object at 0x7f41f74e3518>: Failed to establish a new connection: [Errno 111] Connection refused',))
[2020-03-31 18:14:49,609][fake_learner.py][line:  65][    INFO] something wrong with coordinator, HTTPConnectionPool(host='10.5.36.31', port=18294): Max retries exceeded with url: /coordinator/register_learner (Caused by NewConnectionError('<urllib3.connection.HTTPConnection object at 0x7f41f74e3be0>: Failed to establish a new connection: [Errno 111] Connection refused',))
[2020-03-31 18:14:59,630][fake_learner.py][line:  65][    INFO] something wrong with coordinator, HTTPConnectionPool(host='10.5.36.31', port=18294): Max retries exceeded with url: /coordinator/register_learner (Caused by NewConnectionError('<urllib3.connection.HTTPConnection object at 0x7f41f74c12e8>: Failed to establish a new connection: [Errno 111] Connection refused',))
[2020-03-31 18:15:09,650][fake_learner.py][line:  65][    INFO] something wrong with coordinator, HTTPConnectionPool(host='10.5.36.31', port=18294): Max retries exceeded with url: /coordinator/register_learner (Caused by NewConnectionError('<urllib3.connection.HTTPConnection object at 0x7f41f7520c50>: Failed to establish a new connection: [Errno 111] Connection refused',))
[2020-03-31 18:15:19,667][fake_learner.py][line:  65][    INFO] something wrong with coordinator, HTTPConnectionPool(host='10.5.36.31', port=18294): Max retries exceeded with url: /coordinator/register_learner (Caused by NewConnectionError('<urllib3.connection.HTTPConnection object at 0x7f41f7520668>: Failed to establish a new connection: [Errno 111] Connection refused',))
[2020-03-31 18:15:29,686][fake_learner.py][line:  65][    INFO] something wrong with coordinator, HTTPConnectionPool(host='10.5.36.31', port=18294): Max retries exceeded with url: /coordinator/register_learner (Caused by NewConnectionError('<urllib3.connection.HTTPConnection object at 0x7f41f74e3e80>: Failed to establish a new connection: [Errno 111] Connection refused',))
[2020-03-31 18:15:39,695][fake_learner.py][line:  65][    INFO] something wrong with coordinator, HTTPConnectionPool(host='10.5.36.31', port=18294): Max retries exceeded with url: /coordinator/register_learner (Caused by NewConnectionError('<urllib3.connection.HTTPConnection object at 0x7f41f74e37b8>: Failed to establish a new connection: [Errno 111] Connection refused',))
[2020-03-31 18:15:49,707][fake_learner.py][line:  65][    INFO] something wrong with coordinator, HTTPConnectionPool(host='10.5.36.31', port=18294): Max retries exceeded with url: /coordinator/register_learner (Caused by NewConnectionError('<urllib3.connection.HTTPConnection object at 0x7f41f74e3048>: Failed to establish a new connection: [Errno 111] Connection refused',))
[2020-03-31 18:15:59,779][fake_learner.py][line:  65][    INFO] something wrong with coordinator, HTTPConnectionPool(host='10.5.36.31', port=18294): Max retries exceeded with url: /coordinator/register_learner (Caused by NewConnectionError('<urllib3.connection.HTTPConnection object at 0x7f41f74c1be0>: Failed to establish a new connection: [Errno 111] Connection refused',))
[2020-03-31 18:16:09,802][fake_learner.py][line:  65][    INFO] something wrong with coordinator, HTTPConnectionPool(host='10.5.36.31', port=18294): Max retries exceeded with url: /coordinator/register_learner (Caused by NewConnectionError('<urllib3.connection.HTTPConnection object at 0x7f41f74c62e8>: Failed to establish a new connection: [Errno 111] Connection refused',))
[2020-03-31 18:16:19,816][fake_learner.py][line:  65][    INFO] something wrong with coordinator, HTTPConnectionPool(host='10.5.36.31', port=18294): Max retries exceeded with url: /coordinator/register_learner (Caused by NewConnectionError('<urllib3.connection.HTTPConnection object at 0x7f41f74c69b0>: Failed to establish a new connection: [Errno 111] Connection refused',))
[2020-03-31 18:16:29,834][fake_learner.py][line:  65][    INFO] something wrong with coordinator, HTTPConnectionPool(host='10.5.36.31', port=18294): Max retries exceeded with url: /coordinator/register_learner (Caused by NewConnectionError('<urllib3.connection.HTTPConnection object at 0x7f41f74c1908>: Failed to establish a new connection: [Errno 111] Connection refused',))
[2020-03-31 18:16:39,850][fake_learner.py][line:  65][    INFO] something wrong with coordinator, HTTPConnectionPool(host='10.5.36.31', port=18294): Max retries exceeded with url: /coordinator/register_learner (Caused by NewConnectionError('<urllib3.connection.HTTPConnection object at 0x7f41f74c1400>: Failed to establish a new connection: [Errno 111] Connection refused',))
[2020-03-31 18:16:49,870][fake_learner.py][line:  65][    INFO] something wrong with coordinator, HTTPConnectionPool(host='10.5.36.31', port=18294): Max retries exceeded with url: /coordinator/register_learner (Caused by NewConnectionError('<urllib3.connection.HTTPConnection object at 0x7f41f7520be0>: Failed to establish a new connection: [Errno 111] Connection refused',))
[2020-03-31 18:16:59,886][fake_learner.py][line:  65][    INFO] something wrong with coordinator, HTTPConnectionPool(host='10.5.36.31', port=18294): Max retries exceeded with url: /coordinator/register_learner (Caused by NewConnectionError('<urllib3.connection.HTTPConnection object at 0x7f41f7520f60>: Failed to establish a new connection: [Errno 111] Connection refused',))
[2020-03-31 18:17:09,905][fake_learner.py][line:  65][    INFO] something wrong with coordinator, HTTPConnectionPool(host='10.5.36.31', port=18294): Max retries exceeded with url: /coordinator/register_learner (Caused by NewConnectionError('<urllib3.connection.HTTPConnection object at 0x7f41f74c6be0>: Failed to establish a new connection: [Errno 111] Connection refused',))
[2020-03-31 18:17:19,921][fake_learner.py][line:  65][    INFO] something wrong with coordinator, HTTPConnectionPool(host='10.5.36.31', port=18294): Max retries exceeded with url: /coordinator/register_learner (Caused by NewConnectionError('<urllib3.connection.HTTPConnection object at 0x7f41f74d22e8>: Failed to establish a new connection: [Errno 111] Connection refused',))
[2020-03-31 18:17:29,939][fake_learner.py][line:  65][    INFO] something wrong with coordinator, HTTPConnectionPool(host='10.5.36.31', port=18294): Max retries exceeded with url: /coordinator/register_learner (Caused by NewConnectionError('<urllib3.connection.HTTPConnection object at 0x7f41f74d29b0>: Failed to establish a new connection: [Errno 111] Connection refused',))
[2020-03-31 18:17:40,012][fake_learner.py][line:  65][    INFO] something wrong with coordinator, HTTPConnectionPool(host='10.5.36.31', port=18294): Max retries exceeded with url: /coordinator/register_learner (Caused by NewConnectionError('<urllib3.connection.HTTPConnection object at 0x7f41f74c6be0>: Failed to establish a new connection: [Errno 111] Connection refused',))
[2020-03-31 18:17:50,034][fake_learner.py][line:  65][    INFO] something wrong with coordinator, HTTPConnectionPool(host='10.5.36.31', port=18294): Max retries exceeded with url: /coordinator/register_learner (Caused by NewConnectionError('<urllib3.connection.HTTPConnection object at 0x7f41f7520f60>: Failed to establish a new connection: [Errno 111] Connection refused',))
[2020-03-31 18:18:00,050][fake_learner.py][line:  65][    INFO] something wrong with coordinator, HTTPConnectionPool(host='10.5.36.31', port=18294): Max retries exceeded with url: /coordinator/register_learner (Caused by NewConnectionError('<urllib3.connection.HTTPConnection object at 0x7f41f7520be0>: Failed to establish a new connection: [Errno 111] Connection refused',))
[2020-03-31 18:18:10,065][fake_learner.py][line:  65][    INFO] something wrong with coordinator, HTTPConnectionPool(host='10.5.36.31', port=18294): Max retries exceeded with url: /coordinator/register_learner (Caused by NewConnectionError('<urllib3.connection.HTTPConnection object at 0x7f41f74c14e0>: Failed to establish a new connection: [Errno 111] Connection refused',))
[2020-03-31 18:18:20,126][fake_learner.py][line:  65][    INFO] something wrong with coordinator, HTTPConnectionPool(host='10.5.36.31', port=18294): Max retries exceeded with url: /coordinator/register_learner (Caused by NewConnectionError('<urllib3.connection.HTTPConnection object at 0x7f41f74c1160>: Failed to establish a new connection: [Errno 111] Connection refused',))
[2020-03-31 18:18:30,145][fake_learner.py][line:  65][    INFO] something wrong with coordinator, HTTPConnectionPool(host='10.5.36.31', port=18294): Max retries exceeded with url: /coordinator/register_learner (Caused by NewConnectionError('<urllib3.connection.HTTPConnection object at 0x7f41f74d29b0>: Failed to establish a new connection: [Errno 111] Connection refused',))
[2020-03-31 18:18:40,163][fake_learner.py][line:  65][    INFO] something wrong with coordinator, HTTPConnectionPool(host='10.5.36.31', port=18294): Max retries exceeded with url: /coordinator/register_learner (Caused by NewConnectionError('<urllib3.connection.HTTPConnection object at 0x7f41f74d2358>: Failed to establish a new connection: [Errno 111] Connection refused',))
[2020-03-31 18:18:50,179][fake_learner.py][line:  65][    INFO] something wrong with coordinator, HTTPConnectionPool(host='10.5.36.31', port=18294): Max retries exceeded with url: /coordinator/register_learner (Caused by NewConnectionError('<urllib3.connection.HTTPConnection object at 0x7f4234b48438>: Failed to establish a new connection: [Errno 111] Connection refused',))
[2020-03-31 18:19:00,196][fake_learner.py][line:  65][    INFO] something wrong with coordinator, HTTPConnectionPool(host='10.5.36.31', port=18294): Max retries exceeded with url: /coordinator/register_learner (Caused by NewConnectionError('<urllib3.connection.HTTPConnection object at 0x7f41f74c1b70>: Failed to establish a new connection: [Errno 111] Connection refused',))
[2020-03-31 18:19:10,213][fake_learner.py][line:  65][    INFO] something wrong with coordinator, HTTPConnectionPool(host='10.5.36.31', port=18294): Max retries exceeded with url: /coordinator/register_learner (Caused by NewConnectionError('<urllib3.connection.HTTPConnection object at 0x7f41f74c11d0>: Failed to establish a new connection: [Errno 111] Connection refused',))
[2020-03-31 18:19:20,230][fake_learner.py][line:  65][    INFO] something wrong with coordinator, HTTPConnectionPool(host='10.5.36.31', port=18294): Max retries exceeded with url: /coordinator/register_learner (Caused by NewConnectionError('<urllib3.connection.HTTPConnection object at 0x7f41f7520048>: Failed to establish a new connection: [Errno 111] Connection refused',))
[2020-03-31 18:19:30,246][fake_learner.py][line:  65][    INFO] something wrong with coordinator, HTTPConnectionPool(host='10.5.36.31', port=18294): Max retries exceeded with url: /coordinator/register_learner (Caused by NewConnectionError('<urllib3.connection.HTTPConnection object at 0x7f41f7520c88>: Failed to establish a new connection: [Errno 111] Connection refused',))
[2020-03-31 18:19:40,259][fake_learner.py][line:  65][    INFO] something wrong with coordinator, HTTPConnectionPool(host='10.5.36.31', port=18294): Max retries exceeded with url: /coordinator/register_learner (Caused by NewConnectionError('<urllib3.connection.HTTPConnection object at 0x7f41f74c6ac8>: Failed to establish a new connection: [Errno 111] Connection refused',))
[2020-03-31 18:19:50,275][fake_learner.py][line:  65][    INFO] something wrong with coordinator, HTTPConnectionPool(host='10.5.36.31', port=18294): Max retries exceeded with url: /coordinator/register_learner (Caused by NewConnectionError('<urllib3.connection.HTTPConnection object at 0x7f41f74d2470>: Failed to establish a new connection: [Errno 111] Connection refused',))
[2020-03-31 18:20:00,294][fake_learner.py][line:  65][    INFO] something wrong with coordinator, HTTPConnectionPool(host='10.5.36.31', port=18294): Max retries exceeded with url: /coordinator/register_learner (Caused by NewConnectionError('<urllib3.connection.HTTPConnection object at 0x7f41f74ef0b8>: Failed to establish a new connection: [Errno 111] Connection refused',))
[2020-03-31 18:20:10,360][fake_learner.py][line:  65][    INFO] something wrong with coordinator, HTTPConnectionPool(host='10.5.36.31', port=18294): Max retries exceeded with url: /coordinator/register_learner (Caused by NewConnectionError('<urllib3.connection.HTTPConnection object at 0x7f41f74c6a58>: Failed to establish a new connection: [Errno 111] Connection refused',))
[2020-03-31 18:20:20,384][fake_learner.py][line:  65][    INFO] something wrong with coordinator, HTTPConnectionPool(host='10.5.36.31', port=18294): Max retries exceeded with url: /coordinator/register_learner (Caused by NewConnectionError('<urllib3.connection.HTTPConnection object at 0x7f41f7520f28>: Failed to establish a new connection: [Errno 111] Connection refused',))
[2020-03-31 18:20:30,400][fake_learner.py][line:  65][    INFO] something wrong with coordinator, HTTPConnectionPool(host='10.5.36.31', port=18294): Max retries exceeded with url: /coordinator/register_learner (Caused by NewConnectionError('<urllib3.connection.HTTPConnection object at 0x7f4226f9ca20>: Failed to establish a new connection: [Errno 111] Connection refused',))
[2020-03-31 18:20:40,416][fake_learner.py][line:  65][    INFO] something wrong with coordinator, HTTPConnectionPool(host='10.5.36.31', port=18294): Max retries exceeded with url: /coordinator/register_learner (Caused by NewConnectionError('<urllib3.connection.HTTPConnection object at 0x7f41f74d2198>: Failed to establish a new connection: [Errno 111] Connection refused',))
[2020-03-31 18:20:50,433][fake_learner.py][line:  65][    INFO] something wrong with coordinator, HTTPConnectionPool(host='10.5.36.31', port=18294): Max retries exceeded with url: /coordinator/register_learner (Caused by NewConnectionError('<urllib3.connection.HTTPConnection object at 0x7f41f74c1470>: Failed to establish a new connection: [Errno 111] Connection refused',))
[2020-03-31 18:21:00,445][fake_learner.py][line:  65][    INFO] something wrong with coordinator, HTTPConnectionPool(host='10.5.36.31', port=18294): Max retries exceeded with url: /coordinator/register_learner (Caused by NewConnectionError('<urllib3.connection.HTTPConnection object at 0x7f41f74c1940>: Failed to establish a new connection: [Errno 111] Connection refused',))
[2020-03-31 18:21:10,461][fake_learner.py][line:  65][    INFO] something wrong with coordinator, HTTPConnectionPool(host='10.5.36.31', port=18294): Max retries exceeded with url: /coordinator/register_learner (Caused by NewConnectionError('<urllib3.connection.HTTPConnection object at 0x7f41f750af60>: Failed to establish a new connection: [Errno 111] Connection refused',))
[2020-03-31 18:21:20,471][fake_learner.py][line:  65][    INFO] something wrong with coordinator, HTTPConnectionPool(host='10.5.36.31', port=18294): Max retries exceeded with url: /coordinator/register_learner (Caused by NewConnectionError('<urllib3.connection.HTTPConnection object at 0x7f41f74c1d30>: Failed to establish a new connection: [Errno 111] Connection refused',))
[2020-03-31 18:21:30,484][fake_learner.py][line:  65][    INFO] something wrong with coordinator, HTTPConnectionPool(host='10.5.36.31', port=18294): Max retries exceeded with url: /coordinator/register_learner (Caused by NewConnectionError('<urllib3.connection.HTTPConnection object at 0x7f41f74c12b0>: Failed to establish a new connection: [Errno 111] Connection refused',))
[2020-03-31 18:21:40,537][fake_learner.py][line:  65][    INFO] something wrong with coordinator, HTTPConnectionPool(host='10.5.36.31', port=18294): Max retries exceeded with url: /coordinator/register_learner (Caused by NewConnectionError('<urllib3.connection.HTTPConnection object at 0x7f41f74d2dd8>: Failed to establish a new connection: [Errno 111] Connection refused',))
[2020-03-31 18:21:50,558][fake_learner.py][line:  65][    INFO] something wrong with coordinator, HTTPConnectionPool(host='10.5.36.31', port=18294): Max retries exceeded with url: /coordinator/register_learner (Caused by NewConnectionError('<urllib3.connection.HTTPConnection object at 0x7f41f74d2048>: Failed to establish a new connection: [Errno 111] Connection refused',))
[2020-03-31 18:22:00,574][fake_learner.py][line:  65][    INFO] something wrong with coordinator, HTTPConnectionPool(host='10.5.36.31', port=18294): Max retries exceeded with url: /coordinator/register_learner (Caused by NewConnectionError('<urllib3.connection.HTTPConnection object at 0x7f41f7520e10>: Failed to establish a new connection: [Errno 111] Connection refused',))
[2020-03-31 18:22:10,590][fake_learner.py][line:  65][    INFO] something wrong with coordinator, HTTPConnectionPool(host='10.5.36.31', port=18294): Max retries exceeded with url: /coordinator/register_learner (Caused by NewConnectionError('<urllib3.connection.HTTPConnection object at 0x7f41f74c6320>: Failed to establish a new connection: [Errno 111] Connection refused',))
[2020-03-31 18:22:20,605][fake_learner.py][line:  65][    INFO] something wrong with coordinator, HTTPConnectionPool(host='10.5.36.31', port=18294): Max retries exceeded with url: /coordinator/register_learner (Caused by NewConnectionError('<urllib3.connection.HTTPConnection object at 0x7f41f74c6f28>: Failed to establish a new connection: [Errno 111] Connection refused',))
[2020-03-31 18:22:30,625][fake_learner.py][line:  65][    INFO] something wrong with coordinator, HTTPConnectionPool(host='10.5.36.31', port=18294): Max retries exceeded with url: /coordinator/register_learner (Caused by NewConnectionError('<urllib3.connection.HTTPConnection object at 0x7f41f74c6ac8>: Failed to establish a new connection: [Errno 111] Connection refused',))
[2020-03-31 18:22:40,642][fake_learner.py][line:  65][    INFO] something wrong with coordinator, HTTPConnectionPool(host='10.5.36.31', port=18294): Max retries exceeded with url: /coordinator/register_learner (Caused by NewConnectionError('<urllib3.connection.HTTPConnection object at 0x7f41f7520b70>: Failed to establish a new connection: [Errno 111] Connection refused',))
[2020-03-31 18:22:50,657][fake_learner.py][line:  65][    INFO] something wrong with coordinator, HTTPConnectionPool(host='10.5.36.31', port=18294): Max retries exceeded with url: /coordinator/register_learner (Caused by NewConnectionError('<urllib3.connection.HTTPConnection object at 0x7f41f7520048>: Failed to establish a new connection: [Errno 111] Connection refused',))
[2020-03-31 18:23:00,673][fake_learner.py][line:  65][    INFO] something wrong with coordinator, HTTPConnectionPool(host='10.5.36.31', port=18294): Max retries exceeded with url: /coordinator/register_learner (Caused by NewConnectionError('<urllib3.connection.HTTPConnection object at 0x7f41f74d2320>: Failed to establish a new connection: [Errno 111] Connection refused',))
[2020-03-31 18:23:10,691][fake_learner.py][line:  65][    INFO] something wrong with coordinator, HTTPConnectionPool(host='10.5.36.31', port=18294): Max retries exceeded with url: /coordinator/register_learner (Caused by NewConnectionError('<urllib3.connection.HTTPConnection object at 0x7f41f74c14a8>: Failed to establish a new connection: [Errno 111] Connection refused',))
[2020-03-31 18:23:20,710][fake_learner.py][line:  65][    INFO] something wrong with coordinator, HTTPConnectionPool(host='10.5.36.31', port=18294): Max retries exceeded with url: /coordinator/register_learner (Caused by NewConnectionError('<urllib3.connection.HTTPConnection object at 0x7f41f74c13c8>: Failed to establish a new connection: [Errno 111] Connection refused',))
[2020-03-31 18:23:30,725][fake_learner.py][line:  65][    INFO] something wrong with coordinator, HTTPConnectionPool(host='10.5.36.31', port=18294): Max retries exceeded with url: /coordinator/register_learner (Caused by NewConnectionError('<urllib3.connection.HTTPConnection object at 0x7f41f74c18d0>: Failed to establish a new connection: [Errno 111] Connection refused',))
[2020-03-31 18:23:40,742][fake_learner.py][line:  65][    INFO] something wrong with coordinator, HTTPConnectionPool(host='10.5.36.31', port=18294): Max retries exceeded with url: /coordinator/register_learner (Caused by NewConnectionError('<urllib3.connection.HTTPConnection object at 0x7f41f74ef780>: Failed to establish a new connection: [Errno 111] Connection refused',))
[2020-03-31 18:23:50,758][fake_learner.py][line:  65][    INFO] something wrong with coordinator, HTTPConnectionPool(host='10.5.36.31', port=18294): Max retries exceeded with url: /coordinator/register_learner (Caused by NewConnectionError('<urllib3.connection.HTTPConnection object at 0x7f41f74c13c8>: Failed to establish a new connection: [Errno 111] Connection refused',))
[2020-03-31 18:24:00,774][fake_learner.py][line:  65][    INFO] something wrong with coordinator, HTTPConnectionPool(host='10.5.36.31', port=18294): Max retries exceeded with url: /coordinator/register_learner (Caused by NewConnectionError('<urllib3.connection.HTTPConnection object at 0x7f41f74d2ef0>: Failed to establish a new connection: [Errno 111] Connection refused',))
[2020-03-31 18:24:10,789][fake_learner.py][line:  65][    INFO] something wrong with coordinator, HTTPConnectionPool(host='10.5.36.31', port=18294): Max retries exceeded with url: /coordinator/register_learner (Caused by NewConnectionError('<urllib3.connection.HTTPConnection object at 0x7f41f74d2c88>: Failed to establish a new connection: [Errno 111] Connection refused',))
[2020-03-31 18:24:20,807][fake_learner.py][line:  65][    INFO] something wrong with coordinator, HTTPConnectionPool(host='10.5.36.31', port=18294): Max retries exceeded with url: /coordinator/register_learner (Caused by NewConnectionError('<urllib3.connection.HTTPConnection object at 0x7f41f7520d30>: Failed to establish a new connection: [Errno 111] Connection refused',))
[2020-03-31 18:24:30,823][fake_learner.py][line:  65][    INFO] something wrong with coordinator, HTTPConnectionPool(host='10.5.36.31', port=18294): Max retries exceeded with url: /coordinator/register_learner (Caused by NewConnectionError('<urllib3.connection.HTTPConnection object at 0x7f41f7520748>: Failed to establish a new connection: [Errno 111] Connection refused',))
[2020-03-31 18:24:40,838][fake_learner.py][line:  65][    INFO] something wrong with coordinator, HTTPConnectionPool(host='10.5.36.31', port=18294): Max retries exceeded with url: /coordinator/register_learner (Caused by NewConnectionError('<urllib3.connection.HTTPConnection object at 0x7f41f74c6e48>: Failed to establish a new connection: [Errno 111] Connection refused',))
[2020-03-31 18:24:50,855][fake_learner.py][line:  65][    INFO] something wrong with coordinator, HTTPConnectionPool(host='10.5.36.31', port=18294): Max retries exceeded with url: /coordinator/register_learner (Caused by NewConnectionError('<urllib3.connection.HTTPConnection object at 0x7f41f74ef320>: Failed to establish a new connection: [Errno 111] Connection refused',))
[2020-03-31 18:25:00,866][fake_learner.py][line:  65][    INFO] something wrong with coordinator, HTTPConnectionPool(host='10.5.36.31', port=18294): Max retries exceeded with url: /coordinator/register_learner (Caused by NewConnectionError('<urllib3.connection.HTTPConnection object at 0x7f41f74c6c18>: Failed to establish a new connection: [Errno 111] Connection refused',))
[2020-03-31 18:25:10,875][fake_learner.py][line:  65][    INFO] something wrong with coordinator, HTTPConnectionPool(host='10.5.36.31', port=18294): Max retries exceeded with url: /coordinator/register_learner (Caused by NewConnectionError('<urllib3.connection.HTTPConnection object at 0x7f41f7520eb8>: Failed to establish a new connection: [Errno 111] Connection refused',))
[2020-03-31 18:25:20,893][fake_learner.py][line:  65][    INFO] something wrong with coordinator, HTTPConnectionPool(host='10.5.36.31', port=18294): Max retries exceeded with url: /coordinator/register_learner (Caused by NewConnectionError('<urllib3.connection.HTTPConnection object at 0x7f41f7520198>: Failed to establish a new connection: [Errno 111] Connection refused',))
[2020-03-31 18:25:30,909][fake_learner.py][line:  65][    INFO] something wrong with coordinator, HTTPConnectionPool(host='10.5.36.31', port=18294): Max retries exceeded with url: /coordinator/register_learner (Caused by NewConnectionError('<urllib3.connection.HTTPConnection object at 0x7f41f74d2828>: Failed to establish a new connection: [Errno 111] Connection refused',))
[2020-03-31 18:25:40,927][fake_learner.py][line:  65][    INFO] something wrong with coordinator, HTTPConnectionPool(host='10.5.36.31', port=18294): Max retries exceeded with url: /coordinator/register_learner (Caused by NewConnectionError('<urllib3.connection.HTTPConnection object at 0x7f41f74c1390>: Failed to establish a new connection: [Errno 111] Connection refused',))
[2020-03-31 18:25:50,943][fake_learner.py][line:  65][    INFO] something wrong with coordinator, HTTPConnectionPool(host='10.5.36.31', port=18294): Max retries exceeded with url: /coordinator/register_learner (Caused by NewConnectionError('<urllib3.connection.HTTPConnection object at 0x7f41f74c13c8>: Failed to establish a new connection: [Errno 111] Connection refused',))
[2020-03-31 18:26:00,958][fake_learner.py][line:  65][    INFO] something wrong with coordinator, HTTPConnectionPool(host='10.5.36.31', port=18294): Max retries exceeded with url: /coordinator/register_learner (Caused by NewConnectionError('<urllib3.connection.HTTPConnection object at 0x7f41f74ef6a0>: Failed to establish a new connection: [Errno 111] Connection refused',))
[2020-03-31 18:26:10,974][fake_learner.py][line:  65][    INFO] something wrong with coordinator, HTTPConnectionPool(host='10.5.36.31', port=18294): Max retries exceeded with url: /coordinator/register_learner (Caused by NewConnectionError('<urllib3.connection.HTTPConnection object at 0x7f41f74c1828>: Failed to establish a new connection: [Errno 111] Connection refused',))
[2020-03-31 18:26:20,995][fake_learner.py][line:  65][    INFO] something wrong with coordinator, HTTPConnectionPool(host='10.5.36.31', port=18294): Max retries exceeded with url: /coordinator/register_learner (Caused by NewConnectionError('<urllib3.connection.HTTPConnection object at 0x7f41f74c1a20>: Failed to establish a new connection: [Errno 111] Connection refused',))
[2020-03-31 18:26:31,011][fake_learner.py][line:  65][    INFO] something wrong with coordinator, HTTPConnectionPool(host='10.5.36.31', port=18294): Max retries exceeded with url: /coordinator/register_learner (Caused by NewConnectionError('<urllib3.connection.HTTPConnection object at 0x7f41f74d2240>: Failed to establish a new connection: [Errno 111] Connection refused',))
[2020-03-31 18:26:41,027][fake_learner.py][line:  65][    INFO] something wrong with coordinator, HTTPConnectionPool(host='10.5.36.31', port=18294): Max retries exceeded with url: /coordinator/register_learner (Caused by NewConnectionError('<urllib3.connection.HTTPConnection object at 0x7f41f74d22b0>: Failed to establish a new connection: [Errno 111] Connection refused',))
[2020-03-31 18:26:51,046][fake_learner.py][line:  65][    INFO] something wrong with coordinator, HTTPConnectionPool(host='10.5.36.31', port=18294): Max retries exceeded with url: /coordinator/register_learner (Caused by NewConnectionError('<urllib3.connection.HTTPConnection object at 0x7f41f7520c88>: Failed to establish a new connection: [Errno 111] Connection refused',))
[2020-03-31 18:27:01,062][fake_learner.py][line:  65][    INFO] something wrong with coordinator, HTTPConnectionPool(host='10.5.36.31', port=18294): Max retries exceeded with url: /coordinator/register_learner (Caused by NewConnectionError('<urllib3.connection.HTTPConnection object at 0x7f41f74c62b0>: Failed to establish a new connection: [Errno 111] Connection refused',))
[2020-03-31 18:27:11,077][fake_learner.py][line:  65][    INFO] something wrong with coordinator, HTTPConnectionPool(host='10.5.36.31', port=18294): Max retries exceeded with url: /coordinator/register_learner (Caused by NewConnectionError('<urllib3.connection.HTTPConnection object at 0x7f41f74c6ba8>: Failed to establish a new connection: [Errno 111] Connection refused',))
[2020-03-31 18:27:21,098][fake_learner.py][line:  65][    INFO] something wrong with coordinator, HTTPConnectionPool(host='10.5.36.31', port=18294): Max retries exceeded with url: /coordinator/register_learner (Caused by NewConnectionError('<urllib3.connection.HTTPConnection object at 0x7f41f74efe48>: Failed to establish a new connection: [Errno 111] Connection refused',))
[2020-03-31 18:27:31,114][fake_learner.py][line:  65][    INFO] something wrong with coordinator, HTTPConnectionPool(host='10.5.36.31', port=18294): Max retries exceeded with url: /coordinator/register_learner (Caused by NewConnectionError('<urllib3.connection.HTTPConnection object at 0x7f41f7520828>: Failed to establish a new connection: [Errno 111] Connection refused',))
[2020-03-31 18:27:41,130][fake_learner.py][line:  65][    INFO] something wrong with coordinator, HTTPConnectionPool(host='10.5.36.31', port=18294): Max retries exceeded with url: /coordinator/register_learner (Caused by NewConnectionError('<urllib3.connection.HTTPConnection object at 0x7f41f74c6b38>: Failed to establish a new connection: [Errno 111] Connection refused',))
[2020-03-31 18:27:51,146][fake_learner.py][line:  65][    INFO] something wrong with coordinator, HTTPConnectionPool(host='10.5.36.31', port=18294): Max retries exceeded with url: /coordinator/register_learner (Caused by NewConnectionError('<urllib3.connection.HTTPConnection object at 0x7f41f74c67b8>: Failed to establish a new connection: [Errno 111] Connection refused',))
[2020-03-31 18:28:01,160][fake_learner.py][line:  65][    INFO] something wrong with coordinator, HTTPConnectionPool(host='10.5.36.31', port=18294): Max retries exceeded with url: /coordinator/register_learner (Caused by NewConnectionError('<urllib3.connection.HTTPConnection object at 0x7f41f74c6390>: Failed to establish a new connection: [Errno 111] Connection refused',))
[2020-03-31 18:28:11,241][fake_learner.py][line:  65][    INFO] something wrong with coordinator, HTTPConnectionPool(host='10.5.36.31', port=18294): Max retries exceeded with url: /coordinator/register_learner (Caused by NewConnectionError('<urllib3.connection.HTTPConnection object at 0x7f41f74ef278>: Failed to establish a new connection: [Errno 111] Connection refused',))
[2020-03-31 18:28:21,260][fake_learner.py][line:  65][    INFO] something wrong with coordinator, HTTPConnectionPool(host='10.5.36.31', port=18294): Max retries exceeded with url: /coordinator/register_learner (Caused by NewConnectionError('<urllib3.connection.HTTPConnection object at 0x7f41f74c32e8>: Failed to establish a new connection: [Errno 111] Connection refused',))
[2020-03-31 18:28:31,276][fake_learner.py][line:  65][    INFO] something wrong with coordinator, HTTPConnectionPool(host='10.5.36.31', port=18294): Max retries exceeded with url: /coordinator/register_learner (Caused by NewConnectionError('<urllib3.connection.HTTPConnection object at 0x7f41f74c39b0>: Failed to establish a new connection: [Errno 111] Connection refused',))
[2020-03-31 18:28:41,293][fake_learner.py][line:  65][    INFO] something wrong with coordinator, HTTPConnectionPool(host='10.5.36.31', port=18294): Max retries exceeded with url: /coordinator/register_learner (Caused by NewConnectionError('<urllib3.connection.HTTPConnection object at 0x7f41f74ef5c0>: Failed to establish a new connection: [Errno 111] Connection refused',))
[2020-03-31 18:28:51,309][fake_learner.py][line:  65][    INFO] something wrong with coordinator, HTTPConnectionPool(host='10.5.36.31', port=18294): Max retries exceeded with url: /coordinator/register_learner (Caused by NewConnectionError('<urllib3.connection.HTTPConnection object at 0x7f41f74c6550>: Failed to establish a new connection: [Errno 111] Connection refused',))
[2020-03-31 18:29:01,325][fake_learner.py][line:  65][    INFO] something wrong with coordinator, HTTPConnectionPool(host='10.5.36.31', port=18294): Max retries exceeded with url: /coordinator/register_learner (Caused by NewConnectionError('<urllib3.connection.HTTPConnection object at 0x7f41f74c6e10>: Failed to establish a new connection: [Errno 111] Connection refused',))
[2020-03-31 18:29:11,343][fake_learner.py][line:  65][    INFO] something wrong with coordinator, HTTPConnectionPool(host='10.5.36.31', port=18294): Max retries exceeded with url: /coordinator/register_learner (Caused by NewConnectionError('<urllib3.connection.HTTPConnection object at 0x7f4226f9ca20>: Failed to establish a new connection: [Errno 111] Connection refused',))
[2020-03-31 18:29:21,358][fake_learner.py][line:  65][    INFO] something wrong with coordinator, HTTPConnectionPool(host='10.5.36.31', port=18294): Max retries exceeded with url: /coordinator/register_learner (Caused by NewConnectionError('<urllib3.connection.HTTPConnection object at 0x7f41f7520080>: Failed to establish a new connection: [Errno 111] Connection refused',))
[2020-03-31 18:29:31,370][fake_learner.py][line:  65][    INFO] something wrong with coordinator, HTTPConnectionPool(host='10.5.36.31', port=18294): Max retries exceeded with url: /coordinator/register_learner (Caused by NewConnectionError('<urllib3.connection.HTTPConnection object at 0x7f41f7520ef0>: Failed to establish a new connection: [Errno 111] Connection refused',))
[2020-03-31 18:29:41,450][fake_learner.py][line:  65][    INFO] something wrong with coordinator, HTTPConnectionPool(host='10.5.36.31', port=18294): Max retries exceeded with url: /coordinator/register_learner (Caused by NewConnectionError('<urllib3.connection.HTTPConnection object at 0x7f41f74c32e8>: Failed to establish a new connection: [Errno 111] Connection refused',))
[2020-03-31 18:29:51,471][fake_learner.py][line:  65][    INFO] something wrong with coordinator, HTTPConnectionPool(host='10.5.36.31', port=18294): Max retries exceeded with url: /coordinator/register_learner (Caused by NewConnectionError('<urllib3.connection.HTTPConnection object at 0x7f41f7520b38>: Failed to establish a new connection: [Errno 111] Connection refused',))
[2020-03-31 18:30:01,487][fake_learner.py][line:  65][    INFO] something wrong with coordinator, HTTPConnectionPool(host='10.5.36.31', port=18294): Max retries exceeded with url: /coordinator/register_learner (Caused by NewConnectionError('<urllib3.connection.HTTPConnection object at 0x7f41f75206d8>: Failed to establish a new connection: [Errno 111] Connection refused',))
[2020-03-31 18:30:11,502][fake_learner.py][line:  65][    INFO] something wrong with coordinator, HTTPConnectionPool(host='10.5.36.31', port=18294): Max retries exceeded with url: /coordinator/register_learner (Caused by NewConnectionError('<urllib3.connection.HTTPConnection object at 0x7f41f74c65f8>: Failed to establish a new connection: [Errno 111] Connection refused',))
[2020-03-31 18:30:21,517][fake_learner.py][line:  65][    INFO] something wrong with coordinator, HTTPConnectionPool(host='10.5.36.31', port=18294): Max retries exceeded with url: /coordinator/register_learner (Caused by NewConnectionError('<urllib3.connection.HTTPConnection object at 0x7f41f74c67b8>: Failed to establish a new connection: [Errno 111] Connection refused',))
[2020-03-31 18:30:31,536][fake_learner.py][line:  65][    INFO] something wrong with coordinator, HTTPConnectionPool(host='10.5.36.31', port=18294): Max retries exceeded with url: /coordinator/register_learner (Caused by NewConnectionError('<urllib3.connection.HTTPConnection object at 0x7f41f74c3f28>: Failed to establish a new connection: [Errno 111] Connection refused',))
[2020-03-31 18:30:41,552][fake_learner.py][line:  65][    INFO] something wrong with coordinator, HTTPConnectionPool(host='10.5.36.31', port=18294): Max retries exceeded with url: /coordinator/register_learner (Caused by NewConnectionError('<urllib3.connection.HTTPConnection object at 0x7f41f74c3a90>: Failed to establish a new connection: [Errno 111] Connection refused',))
[2020-03-31 18:30:51,567][fake_learner.py][line:  65][    INFO] something wrong with coordinator, HTTPConnectionPool(host='10.5.36.31', port=18294): Max retries exceeded with url: /coordinator/register_learner (Caused by NewConnectionError('<urllib3.connection.HTTPConnection object at 0x7f41f74efd30>: Failed to establish a new connection: [Errno 111] Connection refused',))
[2020-03-31 18:31:01,586][fake_learner.py][line:  65][    INFO] something wrong with coordinator, HTTPConnectionPool(host='10.5.36.31', port=18294): Max retries exceeded with url: /coordinator/register_learner (Caused by NewConnectionError('<urllib3.connection.HTTPConnection object at 0x7f41f74d28d0>: Failed to establish a new connection: [Errno 111] Connection refused',))
[2020-03-31 18:31:11,601][fake_learner.py][line:  65][    INFO] something wrong with coordinator, HTTPConnectionPool(host='10.5.36.31', port=18294): Max retries exceeded with url: /coordinator/register_learner (Caused by NewConnectionError('<urllib3.connection.HTTPConnection object at 0x7f41f74ef2b0>: Failed to establish a new connection: [Errno 111] Connection refused',))
[2020-03-31 18:31:21,616][fake_learner.py][line:  65][    INFO] something wrong with coordinator, HTTPConnectionPool(host='10.5.36.31', port=18294): Max retries exceeded with url: /coordinator/register_learner (Caused by NewConnectionError('<urllib3.connection.HTTPConnection object at 0x7f41f74c6748>: Failed to establish a new connection: [Errno 111] Connection refused',))
[2020-03-31 18:31:31,632][fake_learner.py][line:  65][    INFO] something wrong with coordinator, HTTPConnectionPool(host='10.5.36.31', port=18294): Max retries exceeded with url: /coordinator/register_learner (Caused by NewConnectionError('<urllib3.connection.HTTPConnection object at 0x7f41f74c6518>: Failed to establish a new connection: [Errno 111] Connection refused',))
[2020-03-31 18:31:41,645][fake_learner.py][line:  65][    INFO] something wrong with coordinator, HTTPConnectionPool(host='10.5.36.31', port=18294): Max retries exceeded with url: /coordinator/register_learner (Caused by NewConnectionError('<urllib3.connection.HTTPConnection object at 0x7f41f750af60>: Failed to establish a new connection: [Errno 111] Connection refused',))
[2020-03-31 18:31:51,664][fake_learner.py][line:  65][    INFO] something wrong with coordinator, HTTPConnectionPool(host='10.5.36.31', port=18294): Max retries exceeded with url: /coordinator/register_learner (Caused by NewConnectionError('<urllib3.connection.HTTPConnection object at 0x7f41f7520e10>: Failed to establish a new connection: [Errno 111] Connection refused',))
[2020-03-31 18:32:01,677][fake_learner.py][line:  65][    INFO] something wrong with coordinator, HTTPConnectionPool(host='10.5.36.31', port=18294): Max retries exceeded with url: /coordinator/register_learner (Caused by NewConnectionError('<urllib3.connection.HTTPConnection object at 0x7f41f74d2c88>: Failed to establish a new connection: [Errno 111] Connection refused',))
[2020-03-31 18:32:11,693][fake_learner.py][line:  65][    INFO] something wrong with coordinator, HTTPConnectionPool(host='10.5.36.31', port=18294): Max retries exceeded with url: /coordinator/register_learner (Caused by NewConnectionError('<urllib3.connection.HTTPConnection object at 0x7f41f74d2eb8>: Failed to establish a new connection: [Errno 111] Connection refused',))
[2020-03-31 18:32:21,708][fake_learner.py][line:  65][    INFO] something wrong with coordinator, HTTPConnectionPool(host='10.5.36.31', port=18294): Max retries exceeded with url: /coordinator/register_learner (Caused by NewConnectionError('<urllib3.connection.HTTPConnection object at 0x7f41f7520c50>: Failed to establish a new connection: [Errno 111] Connection refused',))
[2020-03-31 18:32:31,732][fake_learner.py][line:  65][    INFO] something wrong with coordinator, HTTPConnectionPool(host='10.5.36.31', port=18294): Max retries exceeded with url: /coordinator/register_learner (Caused by NewConnectionError('<urllib3.connection.HTTPConnection object at 0x7f41f7520f98>: Failed to establish a new connection: [Errno 111] Connection refused',))
[2020-03-31 18:32:41,748][fake_learner.py][line:  65][    INFO] something wrong with coordinator, HTTPConnectionPool(host='10.5.36.31', port=18294): Max retries exceeded with url: /coordinator/register_learner (Caused by NewConnectionError('<urllib3.connection.HTTPConnection object at 0x7f41f74c6cf8>: Failed to establish a new connection: [Errno 111] Connection refused',))
[2020-03-31 18:32:51,766][fake_learner.py][line:  65][    INFO] something wrong with coordinator, HTTPConnectionPool(host='10.5.36.31', port=18294): Max retries exceeded with url: /coordinator/register_learner (Caused by NewConnectionError('<urllib3.connection.HTTPConnection object at 0x7f41f74c67f0>: Failed to establish a new connection: [Errno 111] Connection refused',))
[2020-03-31 18:33:01,785][fake_learner.py][line:  65][    INFO] something wrong with coordinator, HTTPConnectionPool(host='10.5.36.31', port=18294): Max retries exceeded with url: /coordinator/register_learner (Caused by NewConnectionError('<urllib3.connection.HTTPConnection object at 0x7f41f74d29e8>: Failed to establish a new connection: [Errno 111] Connection refused',))
[2020-03-31 18:33:11,804][fake_learner.py][line:  65][    INFO] something wrong with coordinator, HTTPConnectionPool(host='10.5.36.31', port=18294): Max retries exceeded with url: /coordinator/register_learner (Caused by NewConnectionError('<urllib3.connection.HTTPConnection object at 0x7f41f74d20f0>: Failed to establish a new connection: [Errno 111] Connection refused',))
[2020-03-31 18:33:21,820][fake_learner.py][line:  65][    INFO] something wrong with coordinator, HTTPConnectionPool(host='10.5.36.31', port=18294): Max retries exceeded with url: /coordinator/register_learner (Caused by NewConnectionError('<urllib3.connection.HTTPConnection object at 0x7f41f74ef1d0>: Failed to establish a new connection: [Errno 111] Connection refused',))
[2020-03-31 18:33:31,876][fake_learner.py][line:  65][    INFO] something wrong with coordinator, HTTPConnectionPool(host='10.5.36.31', port=18294): Max retries exceeded with url: /coordinator/register_learner (Caused by NewConnectionError('<urllib3.connection.HTTPConnection object at 0x7f41f74e10b8>: Failed to establish a new connection: [Errno 111] Connection refused',))
[2020-03-31 18:33:41,898][fake_learner.py][line:  65][    INFO] something wrong with coordinator, HTTPConnectionPool(host='10.5.36.31', port=18294): Max retries exceeded with url: /coordinator/register_learner (Caused by NewConnectionError('<urllib3.connection.HTTPConnection object at 0x7f41f74eff28>: Failed to establish a new connection: [Errno 111] Connection refused',))
[2020-03-31 18:33:51,914][fake_learner.py][line:  65][    INFO] something wrong with coordinator, HTTPConnectionPool(host='10.5.36.31', port=18294): Max retries exceeded with url: /coordinator/register_learner (Caused by NewConnectionError('<urllib3.connection.HTTPConnection object at 0x7f41f74c6940>: Failed to establish a new connection: [Errno 111] Connection refused',))
[2020-03-31 18:34:01,929][fake_learner.py][line:  65][    INFO] something wrong with coordinator, HTTPConnectionPool(host='10.5.36.31', port=18294): Max retries exceeded with url: /coordinator/register_learner (Caused by NewConnectionError('<urllib3.connection.HTTPConnection object at 0x7f41f74c6128>: Failed to establish a new connection: [Errno 111] Connection refused',))
[2020-03-31 18:34:12,018][fake_learner.py][line:  65][    INFO] something wrong with coordinator, HTTPConnectionPool(host='10.5.36.31', port=18294): Max retries exceeded with url: /coordinator/register_learner (Caused by NewConnectionError('<urllib3.connection.HTTPConnection object at 0x7f41f750aef0>: Failed to establish a new connection: [Errno 111] Connection refused',))
[2020-03-31 18:34:22,038][fake_learner.py][line:  65][    INFO] something wrong with coordinator, HTTPConnectionPool(host='10.5.36.31', port=18294): Max retries exceeded with url: /coordinator/register_learner (Caused by NewConnectionError('<urllib3.connection.HTTPConnection object at 0x7f41f75201d0>: Failed to establish a new connection: [Errno 111] Connection refused',))
[2020-03-31 18:34:32,053][fake_learner.py][line:  65][    INFO] something wrong with coordinator, HTTPConnectionPool(host='10.5.36.31', port=18294): Max retries exceeded with url: /coordinator/register_learner (Caused by NewConnectionError('<urllib3.connection.HTTPConnection object at 0x7f41f74e1048>: Failed to establish a new connection: [Errno 111] Connection refused',))
[2020-03-31 18:34:42,069][fake_learner.py][line:  65][    INFO] something wrong with coordinator, HTTPConnectionPool(host='10.5.36.31', port=18294): Max retries exceeded with url: /coordinator/register_learner (Caused by NewConnectionError('<urllib3.connection.HTTPConnection object at 0x7f41f74e19b0>: Failed to establish a new connection: [Errno 111] Connection refused',))
[2020-03-31 18:34:52,160][fake_learner.py][line:  65][    INFO] something wrong with coordinator, HTTPConnectionPool(host='10.5.36.31', port=18294): Max retries exceeded with url: /coordinator/register_learner (Caused by NewConnectionError('<urllib3.connection.HTTPConnection object at 0x7f41f7520b70>: Failed to establish a new connection: [Errno 111] Connection refused',))
[2020-03-31 18:35:02,178][fake_learner.py][line:  65][    INFO] something wrong with coordinator, HTTPConnectionPool(host='10.5.36.31', port=18294): Max retries exceeded with url: /coordinator/register_learner (Caused by NewConnectionError('<urllib3.connection.HTTPConnection object at 0x7f41f7520080>: Failed to establish a new connection: [Errno 111] Connection refused',))
[2020-03-31 18:35:12,193][fake_learner.py][line:  65][    INFO] something wrong with coordinator, HTTPConnectionPool(host='10.5.36.31', port=18294): Max retries exceeded with url: /coordinator/register_learner (Caused by NewConnectionError('<urllib3.connection.HTTPConnection object at 0x7f41f74c6a90>: Failed to establish a new connection: [Errno 111] Connection refused',))
[2020-03-31 18:35:22,206][fake_learner.py][line:  65][    INFO] something wrong with coordinator, HTTPConnectionPool(host='10.5.36.31', port=18294): Max retries exceeded with url: /coordinator/register_learner (Caused by NewConnectionError('<urllib3.connection.HTTPConnection object at 0x7f41f74c6710>: Failed to establish a new connection: [Errno 111] Connection refused',))
[2020-03-31 18:35:32,262][fake_learner.py][line:  65][    INFO] something wrong with coordinator, HTTPConnectionPool(host='10.5.36.31', port=18294): Max retries exceeded with url: /coordinator/register_learner (Caused by NewConnectionError('<urllib3.connection.HTTPConnection object at 0x7f41f74e1f28>: Failed to establish a new connection: [Errno 111] Connection refused',))
[2020-03-31 18:35:42,284][fake_learner.py][line:  65][    INFO] something wrong with coordinator, HTTPConnectionPool(host='10.5.36.31', port=18294): Max retries exceeded with url: /coordinator/register_learner (Caused by NewConnectionError('<urllib3.connection.HTTPConnection object at 0x7f41f74e1358>: Failed to establish a new connection: [Errno 111] Connection refused',))
[2020-03-31 18:35:52,297][fake_learner.py][line:  65][    INFO] something wrong with coordinator, HTTPConnectionPool(host='10.5.36.31', port=18294): Max retries exceeded with url: /coordinator/register_learner (Caused by NewConnectionError('<urllib3.connection.HTTPConnection object at 0x7f41f74ef0b8>: Failed to establish a new connection: [Errno 111] Connection refused',))
[2020-03-31 18:36:02,354][fake_learner.py][line:  65][    INFO] something wrong with coordinator, HTTPConnectionPool(host='10.5.36.31', port=18294): Max retries exceeded with url: /coordinator/register_learner (Caused by NewConnectionError('<urllib3.connection.HTTPConnection object at 0x7f41f74d50b8>: Failed to establish a new connection: [Errno 111] Connection refused',))
[2020-03-31 18:36:12,378][fake_learner.py][line:  65][    INFO] something wrong with coordinator, HTTPConnectionPool(host='10.5.36.31', port=18294): Max retries exceeded with url: /coordinator/register_learner (Caused by NewConnectionError('<urllib3.connection.HTTPConnection object at 0x7f41f74ef7f0>: Failed to establish a new connection: [Errno 111] Connection refused',))
[2020-03-31 18:36:22,394][fake_learner.py][line:  65][    INFO] something wrong with coordinator, HTTPConnectionPool(host='10.5.36.31', port=18294): Max retries exceeded with url: /coordinator/register_learner (Caused by NewConnectionError('<urllib3.connection.HTTPConnection object at 0x7f41f74c6198>: Failed to establish a new connection: [Errno 111] Connection refused',))
[2020-03-31 18:36:32,407][fake_learner.py][line:  65][    INFO] something wrong with coordinator, HTTPConnectionPool(host='10.5.36.31', port=18294): Max retries exceeded with url: /coordinator/register_learner (Caused by NewConnectionError('<urllib3.connection.HTTPConnection object at 0x7f41f74c6048>: Failed to establish a new connection: [Errno 111] Connection refused',))
[2020-03-31 18:36:42,460][fake_learner.py][line:  65][    INFO] something wrong with coordinator, HTTPConnectionPool(host='10.5.36.31', port=18294): Max retries exceeded with url: /coordinator/register_learner (Caused by NewConnectionError('<urllib3.connection.HTTPConnection object at 0x7f41f750af28>: Failed to establish a new connection: [Errno 111] Connection refused',))
[2020-03-31 18:36:52,482][fake_learner.py][line:  65][    INFO] something wrong with coordinator, HTTPConnectionPool(host='10.5.36.31', port=18294): Max retries exceeded with url: /coordinator/register_learner (Caused by NewConnectionError('<urllib3.connection.HTTPConnection object at 0x7f41f7520f28>: Failed to establish a new connection: [Errno 111] Connection refused',))
[2020-03-31 18:37:02,498][fake_learner.py][line:  65][    INFO] something wrong with coordinator, HTTPConnectionPool(host='10.5.36.31', port=18294): Max retries exceeded with url: /coordinator/register_learner (Caused by NewConnectionError('<urllib3.connection.HTTPConnection object at 0x7f41f74d5048>: Failed to establish a new connection: [Errno 111] Connection refused',))
[2020-03-31 18:37:12,517][fake_learner.py][line:  65][    INFO] something wrong with coordinator, HTTPConnectionPool(host='10.5.36.31', port=18294): Max retries exceeded with url: /coordinator/register_learner (Caused by NewConnectionError('<urllib3.connection.HTTPConnection object at 0x7f41f74d59b0>: Failed to establish a new connection: [Errno 111] Connection refused',))
[2020-03-31 18:37:22,531][fake_learner.py][line:  65][    INFO] something wrong with coordinator, HTTPConnectionPool(host='10.5.36.31', port=18294): Max retries exceeded with url: /coordinator/register_learner (Caused by NewConnectionError('<urllib3.connection.HTTPConnection object at 0x7f41f7520c18>: Failed to establish a new connection: [Errno 111] Connection refused',))
[2020-03-31 18:37:32,552][fake_learner.py][line:  65][    INFO] something wrong with coordinator, HTTPConnectionPool(host='10.5.36.31', port=18294): Max retries exceeded with url: /coordinator/register_learner (Caused by NewConnectionError('<urllib3.connection.HTTPConnection object at 0x7f41f7520d68>: Failed to establish a new connection: [Errno 111] Connection refused',))
[2020-03-31 18:37:42,568][fake_learner.py][line:  65][    INFO] something wrong with coordinator, HTTPConnectionPool(host='10.5.36.31', port=18294): Max retries exceeded with url: /coordinator/register_learner (Caused by NewConnectionError('<urllib3.connection.HTTPConnection object at 0x7f41f74c6b00>: Failed to establish a new connection: [Errno 111] Connection refused',))
[2020-03-31 18:37:52,583][fake_learner.py][line:  65][    INFO] something wrong with coordinator, HTTPConnectionPool(host='10.5.36.31', port=18294): Max retries exceeded with url: /coordinator/register_learner (Caused by NewConnectionError('<urllib3.connection.HTTPConnection object at 0x7f41f74c6390>: Failed to establish a new connection: [Errno 111] Connection refused',))
[2020-03-31 18:38:02,709][fake_learner.py][line:  65][    INFO] something wrong with coordinator, HTTPConnectionPool(host='10.5.36.31', port=18294): Max retries exceeded with url: /coordinator/register_learner (Caused by NewConnectionError('<urllib3.connection.HTTPConnection object at 0x7f41f74d5f28>: Failed to establish a new connection: [Errno 111] Connection refused',))
[2020-03-31 18:38:12,725][fake_learner.py][line:  65][    INFO] something wrong with coordinator, HTTPConnectionPool(host='10.5.36.31', port=18294): Max retries exceeded with url: /coordinator/register_learner (Caused by NewConnectionError('<urllib3.connection.HTTPConnection object at 0x7f41f74d5358>: Failed to establish a new connection: [Errno 111] Connection refused',))
[2020-03-31 18:38:22,739][fake_learner.py][line:  65][    INFO] something wrong with coordinator, HTTPConnectionPool(host='10.5.36.31', port=18294): Max retries exceeded with url: /coordinator/register_learner (Caused by NewConnectionError('<urllib3.connection.HTTPConnection object at 0x7f41f74efef0>: Failed to establish a new connection: [Errno 111] Connection refused',))
[2020-03-31 18:38:32,764][fake_learner.py][line:  65][    INFO] something wrong with coordinator, HTTPConnectionPool(host='10.5.36.31', port=18294): Max retries exceeded with url: /coordinator/register_learner (Caused by NewConnectionError('<urllib3.connection.HTTPConnection object at 0x7f41f74e10f0>: Failed to establish a new connection: [Errno 111] Connection refused',))
[2020-03-31 18:38:44,463][fake_learner.py][line:  65][    INFO] something wrong with coordinator, HTTPConnectionPool(host='10.5.36.31', port=18294): Max retries exceeded with url: /coordinator/register_learner (Caused by NewConnectionError('<urllib3.connection.HTTPConnection object at 0x7f41f74ef390>: Failed to establish a new connection: [Errno 111] Connection refused',))
[2020-03-31 18:38:54,483][fake_learner.py][line:  65][    INFO] something wrong with coordinator, HTTPConnectionPool(host='10.5.36.31', port=18294): Max retries exceeded with url: /coordinator/register_learner (Caused by NewConnectionError('<urllib3.connection.HTTPConnection object at 0x7f41f74c6320>: Failed to establish a new connection: [Errno 111] Connection refused',))
[2020-03-31 18:39:04,498][fake_learner.py][line:  65][    INFO] something wrong with coordinator, HTTPConnectionPool(host='10.5.36.31', port=18294): Max retries exceeded with url: /coordinator/register_learner (Caused by NewConnectionError('<urllib3.connection.HTTPConnection object at 0x7f41f74c6f28>: Failed to establish a new connection: [Errno 111] Connection refused',))
[2020-03-31 18:39:14,566][fake_learner.py][line:  65][    INFO] something wrong with coordinator, HTTPConnectionPool(host='10.5.36.31', port=18294): Max retries exceeded with url: /coordinator/register_learner (Caused by NewConnectionError('<urllib3.connection.HTTPConnection object at 0x7f41f750ae80>: Failed to establish a new connection: [Errno 111] Connection refused',))
[2020-03-31 18:39:24,591][fake_learner.py][line:  65][    INFO] something wrong with coordinator, HTTPConnectionPool(host='10.5.36.31', port=18294): Max retries exceeded with url: /coordinator/register_learner (Caused by NewConnectionError('<urllib3.connection.HTTPConnection object at 0x7f41f7520da0>: Failed to establish a new connection: [Errno 111] Connection refused',))
[2020-03-31 18:39:34,609][fake_learner.py][line:  65][    INFO] something wrong with coordinator, HTTPConnectionPool(host='10.5.36.31', port=18294): Max retries exceeded with url: /coordinator/register_learner (Caused by NewConnectionError('<urllib3.connection.HTTPConnection object at 0x7f41f74e1208>: Failed to establish a new connection: [Errno 111] Connection refused',))
[2020-03-31 18:39:44,622][fake_learner.py][line:  65][    INFO] something wrong with coordinator, HTTPConnectionPool(host='10.5.36.31', port=18294): Max retries exceeded with url: /coordinator/register_learner (Caused by NewConnectionError('<urllib3.connection.HTTPConnection object at 0x7f41f74e1cc0>: Failed to establish a new connection: [Errno 111] Connection refused',))
[2020-03-31 18:39:54,692][fake_learner.py][line:  65][    INFO] something wrong with coordinator, HTTPConnectionPool(host='10.5.36.31', port=18294): Max retries exceeded with url: /coordinator/register_learner (Caused by NewConnectionError('<urllib3.connection.HTTPConnection object at 0x7f41f7520b38>: Failed to establish a new connection: [Errno 111] Connection refused',))
[2020-03-31 18:40:04,711][fake_learner.py][line:  65][    INFO] something wrong with coordinator, HTTPConnectionPool(host='10.5.36.31', port=18294): Max retries exceeded with url: /coordinator/register_learner (Caused by NewConnectionError('<urllib3.connection.HTTPConnection object at 0x7f41f7520278>: Failed to establish a new connection: [Errno 111] Connection refused',))
[2020-03-31 18:40:14,788][fake_learner.py][line:  65][    INFO] something wrong with coordinator, HTTPConnectionPool(host='10.5.36.31', port=18294): Max retries exceeded with url: /coordinator/register_learner (Caused by NewConnectionError('<urllib3.connection.HTTPConnection object at 0x7f41f74c65f8>: Failed to establish a new connection: [Errno 111] Connection refused',))
[2020-03-31 18:40:24,806][fake_learner.py][line:  65][    INFO] something wrong with coordinator, HTTPConnectionPool(host='10.5.36.31', port=18294): Max retries exceeded with url: /coordinator/register_learner (Caused by NewConnectionError('<urllib3.connection.HTTPConnection object at 0x7f41f74c6240>: Failed to establish a new connection: [Errno 111] Connection refused',))
[2020-03-31 18:40:34,825][fake_learner.py][line:  65][    INFO] something wrong with coordinator, HTTPConnectionPool(host='10.5.36.31', port=18294): Max retries exceeded with url: /coordinator/register_learner (Caused by NewConnectionError('<urllib3.connection.HTTPConnection object at 0x7f41f74e1f60>: Failed to establish a new connection: [Errno 111] Connection refused',))
[2020-03-31 18:40:44,837][fake_learner.py][line:  65][    INFO] something wrong with coordinator, HTTPConnectionPool(host='10.5.36.31', port=18294): Max retries exceeded with url: /coordinator/register_learner (Caused by NewConnectionError('<urllib3.connection.HTTPConnection object at 0x7f41f74e1358>: Failed to establish a new connection: [Errno 111] Connection refused',))
[2020-03-31 18:40:54,896][fake_learner.py][line:  65][    INFO] something wrong with coordinator, HTTPConnectionPool(host='10.5.36.31', port=18294): Max retries exceeded with url: /coordinator/register_learner (Caused by NewConnectionError('<urllib3.connection.HTTPConnection object at 0x7f41f74ef0f0>: Failed to establish a new connection: [Errno 111] Connection refused',))
[2020-03-31 18:41:04,936][fake_learner.py][line:  65][    INFO] something wrong with coordinator, HTTPConnectionPool(host='10.5.36.31', port=18294): Max retries exceeded with url: /coordinator/register_learner (Caused by NewConnectionError('<urllib3.connection.HTTPConnection object at 0x7f41f74cf0b8>: Failed to establish a new connection: [Errno 111] Connection refused',))
[2020-03-31 18:41:14,958][fake_learner.py][line:  65][    INFO] something wrong with coordinator, HTTPConnectionPool(host='10.5.36.31', port=18294): Max retries exceeded with url: /coordinator/register_learner (Caused by NewConnectionError('<urllib3.connection.HTTPConnection object at 0x7f41f74eff60>: Failed to establish a new connection: [Errno 111] Connection refused',))
[2020-03-31 18:41:24,980][fake_learner.py][line:  65][    INFO] something wrong with coordinator, HTTPConnectionPool(host='10.5.36.31', port=18294): Max retries exceeded with url: /coordinator/register_learner (Caused by NewConnectionError('<urllib3.connection.HTTPConnection object at 0x7f41f74c65c0>: Failed to establish a new connection: [Errno 111] Connection refused',))
[2020-03-31 18:41:34,996][fake_learner.py][line:  65][    INFO] something wrong with coordinator, HTTPConnectionPool(host='10.5.36.31', port=18294): Max retries exceeded with url: /coordinator/register_learner (Caused by NewConnectionError('<urllib3.connection.HTTPConnection object at 0x7f41f74c6358>: Failed to establish a new connection: [Errno 111] Connection refused',))
[2020-03-31 18:41:45,011][fake_learner.py][line:  65][    INFO] something wrong with coordinator, HTTPConnectionPool(host='10.5.36.31', port=18294): Max retries exceeded with url: /coordinator/register_learner (Caused by NewConnectionError('<urllib3.connection.HTTPConnection object at 0x7f41f750af60>: Failed to establish a new connection: [Errno 111] Connection refused',))
[2020-03-31 18:41:55,029][fake_learner.py][line:  65][    INFO] something wrong with coordinator, HTTPConnectionPool(host='10.5.36.31', port=18294): Max retries exceeded with url: /coordinator/register_learner (Caused by NewConnectionError('<urllib3.connection.HTTPConnection object at 0x7f41f7520978>: Failed to establish a new connection: [Errno 111] Connection refused',))
[2020-03-31 18:42:05,044][fake_learner.py][line:  65][    INFO] something wrong with coordinator, HTTPConnectionPool(host='10.5.36.31', port=18294): Max retries exceeded with url: /coordinator/register_learner (Caused by NewConnectionError('<urllib3.connection.HTTPConnection object at 0x7f41f74cf048>: Failed to establish a new connection: [Errno 111] Connection refused',))
[2020-03-31 18:42:15,098][fake_learner.py][line:  65][    INFO] something wrong with coordinator, HTTPConnectionPool(host='10.5.36.31', port=18294): Max retries exceeded with url: /coordinator/register_learner (Caused by NewConnectionError('<urllib3.connection.HTTPConnection object at 0x7f41f74cf9b0>: Failed to establish a new connection: [Errno 111] Connection refused',))
[2020-03-31 18:42:25,119][fake_learner.py][line:  65][    INFO] something wrong with coordinator, HTTPConnectionPool(host='10.5.36.31', port=18294): Max retries exceeded with url: /coordinator/register_learner (Caused by NewConnectionError('<urllib3.connection.HTTPConnection object at 0x7f41f7520c50>: Failed to establish a new connection: [Errno 111] Connection refused',))
[2020-03-31 18:42:35,135][fake_learner.py][line:  65][    INFO] something wrong with coordinator, HTTPConnectionPool(host='10.5.36.31', port=18294): Max retries exceeded with url: /coordinator/register_learner (Caused by NewConnectionError('<urllib3.connection.HTTPConnection object at 0x7f41f7520f60>: Failed to establish a new connection: [Errno 111] Connection refused',))
[2020-03-31 18:42:45,151][fake_learner.py][line:  65][    INFO] something wrong with coordinator, HTTPConnectionPool(host='10.5.36.31', port=18294): Max retries exceeded with url: /coordinator/register_learner (Caused by NewConnectionError('<urllib3.connection.HTTPConnection object at 0x7f41f74c6a58>: Failed to establish a new connection: [Errno 111] Connection refused',))
[2020-03-31 18:42:55,203][fake_learner.py][line:  65][    INFO] something wrong with coordinator, HTTPConnectionPool(host='10.5.36.31', port=18294): Max retries exceeded with url: /coordinator/register_learner (Caused by NewConnectionError('<urllib3.connection.HTTPConnection object at 0x7f41f74c69b0>: Failed to establish a new connection: [Errno 111] Connection refused',))
[2020-03-31 18:43:05,226][fake_learner.py][line:  65][    INFO] something wrong with coordinator, HTTPConnectionPool(host='10.5.36.31', port=18294): Max retries exceeded with url: /coordinator/register_learner (Caused by NewConnectionError('<urllib3.connection.HTTPConnection object at 0x7f41f74cff28>: Failed to establish a new connection: [Errno 111] Connection refused',))
[2020-03-31 18:43:15,242][fake_learner.py][line:  65][    INFO] something wrong with coordinator, HTTPConnectionPool(host='10.5.36.31', port=18294): Max retries exceeded with url: /coordinator/register_learner (Caused by NewConnectionError('<urllib3.connection.HTTPConnection object at 0x7f41f74cf358>: Failed to establish a new connection: [Errno 111] Connection refused',))
