[2020-04-01 15:47:40,899][  log_helper.py][line:  99][    INFO] something wrong with coordinator, HTTPConnectionPool(host='10.5.36.31', port=18295): Max retries exceeded with url: /manager/register (Caused by NewConnectionError('<urllib3.connection.HTTPConnection object at 0x7f9be800da58>: Failed to establish a new connection: [Errno 111] Connection refused',))
[2020-04-01 15:47:50,915][  log_helper.py][line:  99][    INFO] something wrong with coordinator, HTTPConnectionPool(host='10.5.36.31', port=18295): Max retries exceeded with url: /manager/register (Caused by NewConnectionError('<urllib3.connection.HTTPConnection object at 0x7f9be80283c8>: Failed to establish a new connection: [Errno 111] Connection refused',))
[2020-04-01 15:48:00,932][  log_helper.py][line:  99][    INFO] something wrong with coordinator, HTTPConnectionPool(host='10.5.36.31', port=18295): Max retries exceeded with url: /manager/register (Caused by NewConnectionError('<urllib3.connection.HTTPConnection object at 0x7f9be8028cf8>: Failed to establish a new connection: [Errno 111] Connection refused',))
[2020-04-01 15:48:10,950][  log_helper.py][line:  99][    INFO] something wrong with coordinator, HTTPConnectionPool(host='10.5.36.31', port=18295): Max retries exceeded with url: /manager/register (Caused by NewConnectionError('<urllib3.connection.HTTPConnection object at 0x7f9be801af60>: Failed to establish a new connection: [Errno 111] Connection refused',))
[2020-04-01 15:48:20,961][  log_helper.py][line:  99][    INFO] something wrong with coordinator, HTTPConnectionPool(host='10.5.36.31', port=18295): Max retries exceeded with url: /manager/register (Caused by NewConnectionError('<urllib3.connection.HTTPConnection object at 0x7f9be8028860>: Failed to establish a new connection: [Errno 111] Connection refused',))
